<sdf version='1.6'>
  <model name='grid_robot_description'>
    <link name='base_link'>
      <pose frame=''>0 0 0 0 -0 0</pose>
      <inertial>
        <pose frame=''>-0.016778 -0 -0.007997 0 -0 0</pose>
        <mass>0.10648</mass>
        <inertia>
          <ixx>4.9956e-05</ixx>
          <ixy>1.6115e-14</ixy>
          <ixz>-4.2649e-10</ixz>
          <iyy>0.00018031</iyy>
          <iyz>-3.1211e-10</iyz>
          <izz>0.00022562</izz>
        </inertia>
      </inertial>
      <collision name='base_link_collision'>
        <pose frame=''>0 0 0 0 -0 0</pose>
        <geometry>
          <mesh>
            <scale>1 1 1</scale>
            <uri>model://grid_robot_description/meshes/base_link.STL</uri>
          </mesh>
        </geometry>
      </collision>
      <visual name='base_link_visual'>
        <pose frame=''>0 0 0 0 -0 0</pose>
        <geometry>
          <mesh>
            <scale>1 1 1</scale>
            <uri>model://grid_robot_description/meshes/base_link.STL</uri>
          </mesh>
        </geometry>
        <material>
          <script>
            <name>Gazebo/Grey</name>
            <uri>file://media/materials/scripts/gazebo.material</uri>
          </script>
        </material>
      </visual>
      <visual name='april_tag_visual'>
        <pose frame=''>0 0 0.001 0 -0 0</pose>
        <geometry>
          <plane>
            <normal>0 0 1</normal>
            <size>0.1 0.1</size>
          </plane>
        </geometry>
        <material>
          <script>
            <uri>model://grid_robot_description/materials/scripts</uri>
            <uri>model://grid_robot_description/materials/textures</uri>
            <name>april_tag/Image</name>
          </script>
        </material>
      </visual>
    </link>
    <link name='left_wheel_link'>
      <pose frame=''>0.00725 0.0755 -0.013684 0 -0 0</pose>
      <inertial>
        <pose frame=''>-0 -0.011873 -0 0 -0 0</pose>
        <mass>0.16695</mass>
        <inertia>
          <ixx>6.7294e-05</ixx>
          <ixy>1.8343e-12</ixy>
          <ixz>1.6475e-09</ixz>
          <iyy>0.00011321</iyy>
          <iyz>2.6313e-12</iyz>
          <izz>6.7295e-05</izz>
        </inertia>
      </inertial>
      <collision name='left_wheel_link_collision'>
        <pose frame=''>0 0 0 0 -0 0</pose>
        <geometry>
          <mesh>
            <scale>1 1 1</scale>
            <uri>model://grid_robot_description/meshes/left_wheel_link.STL</uri>
          </mesh>
        </geometry>
      </collision>
      <visual name='left_wheel_link_visual'>
        <pose frame=''>0 0 0 0 -0 0</pose>
        <geometry>
          <mesh>
            <scale>1 1 1</scale>
            <uri>model://grid_robot_description/meshes/left_wheel_link.STL</uri>
          </mesh>
        </geometry>
        <material>
          <script>
            <name>Gazebo/DarkGrey</name>
            <uri>file://media/materials/scripts/gazebo.material</uri>
          </script>
        </material>
      </visual>
    </link>
    <joint name='left_wheel_joint' type='revolute'>
      <child>left_wheel_link</child>
      <parent>base_link</parent>
      <axis>
        <xyz>0 1 0</xyz>
        <limit>
          <lower>-1e+16</lower>
          <upper>1e+16</upper>
        </limit>
        <dynamics>
          <spring_reference>0</spring_reference>
          <spring_stiffness>0</spring_stiffness>
        </dynamics>
        <use_parent_model_frame>1</use_parent_model_frame>
      </axis>
    </joint>
    <link name='right_wheel_link'>
      <pose frame=''>0.00725 -0.0755 -0.013816 0 -0 0</pose>
      <inertial>
        <pose frame=''>0 0.011873 0 0 -0 0</pose>
        <mass>0.16695</mass>
        <inertia>
          <ixx>6.7294e-05</ixx>
          <ixy>1.7315e-12</ixy>
          <ixz>1.7871e-09</ixz>
          <iyy>0.00011321</iyy>
          <iyz>2.7e-12</iyz>
          <izz>6.7295e-05</izz>
        </inertia>
      </inertial>
      <collision name='right_wheel_link_collision'>
        <pose frame=''>0 0 0 0 -0 0</pose>
        <geometry>
          <mesh>
            <scale>1 1 1</scale>
            <uri>model://grid_robot_description/meshes/right_wheel_link.STL</uri>
          </mesh>
        </geometry>
      </collision>
      <visual name='right_wheel_link_visual'>
        <pose frame=''>0 0 0 0 -0 0</pose>
        <geometry>
          <mesh>
            <scale>1 1 1</scale>
            <uri>model://grid_robot_description/meshes/right_wheel_link.STL</uri>
          </mesh>
        </geometry>
        <material>
          <script>
            <name>Gazebo/DarkGrey</name>
            <uri>file://media/materials/scripts/gazebo.material</uri>
          </script>
        </material>
      </visual>
    </link>
    <joint name='right_wheel_joint' type='revolute'>
      <child>right_wheel_link</child>
      <parent>base_link</parent>
      <axis>
        <xyz>0 1 0</xyz>
        <limit>
          <lower>-1e+16</lower>
          <upper>1e+16</upper>
        </limit>
        <dynamics>
          <spring_reference>0</spring_reference>
          <spring_stiffness>0</spring_stiffness>
        </dynamics>
        <use_parent_model_frame>1</use_parent_model_frame>
      </axis>
    </joint>
    <plugin name='differential_drive_controller' filename='libgazebo_ros_diff_drive.so'>
      <updateRate>100</updateRate>
      <leftJoint>left_wheel_joint</leftJoint>
      <rightJoint>right_wheel_joint</rightJoint>
      <wheelSeparation>0.151</wheelSeparation>
      <wheelDiameter>0.06918</wheelDiameter>
      <wheelAcceleration>1.0</wheelAcceleration>
      <wheelTorque>5</wheelTorque>
      <commandTopic>cmd_vel</commandTopic>
      <odometryTopic>odom</odometryTopic>
      <odometryFrame>odom</odometryFrame>
      <robotBaseFrame>base_footprint</robotBaseFrame>
      <odometrySource>1</odometrySource>
      <publishWheelTF>1</publishWheelTF>
      <publishOdom>1</publishOdom>
      <publishWheelJointState>1</publishWheelJointState>
      <legacyMode>0</legacyMode>
    </plugin>
  </model>
</sdf>
